--TEST--
Test for bug #476: Exception chanining doesn't work
--INI--
xdebug.default_enable=1
xdebug.dump.GET=
xdebug.dump.SERVER=
xdebug.show_local_vars=0
--FILE--
<?php

function a()
{
   throw new Exception('First exception');
}

function b()
{
	try {
		a();
	} catch(Exception $e) {
	   throw new Exception('Second exception', 0, $e);
	}
}

function c()
{
	try {
		b();
	} catch(Exception $e) {
	   throw new Exception('Third exception', 0, $e);
	}
}

function d()
{
	try {
		c();
	} catch(Exception $e) {
	   throw new Exception('Fourth exception', 0, $e);
	}
}

d();

echo "DONE\n";
?>
--EXPECTF--
Fatal error: Uncaught%sFirst exception%sin %sbug00476-002-php7.php%s%d
Stack trace:
#0 %sbug00476-002-php7.php(11): a()
#1 %sbug00476-002-php7.php(20): b()
#2 %sbug00476-002-php7.php(29): c()
#3 %sbug00476-002-php7.php(35): d()
#4 {main}

Next Exception: Second exception in %sbug00476-002-php7.php:13
Stack trace:
#0 %sbug00476-002-php7.php(20): b()
#1 %sbug00476-002-php7.php(29): c()
#2 %sbug00476-002-php7.php(35): d()
#3 {main}

Next Exception: Third exception in %sbug00476-002-php7.php:22
Stack trace:
#0 %sbug00476-002-php7.php(29): c()
#1 %sbug00476-002-php7.php(35): d()
#2 {main}

Next Exception: Fourth exception in %sbug00476-002-php7.php on line 31

Exception: First exception in %sbug00476-002-php7.php on line 5

Call Stack:
%w%f %w%d   1. {main}() %sbug00476-002-php7.php:0
%w%f %w%d   2. d() %sbug00476-002-php7.php:35
%w%f %w%d   3. c() %sbug00476-002-php7.php:29
%w%f %w%d   4. b() %sbug00476-002-php7.php:20
%w%f %w%d   5. a() %sbug00476-002-php7.php:11

Exception: Second exception in %sbug00476-002-php7.php on line 13

Call Stack:
%w%f %w%d   1. {main}() %sbug00476-002-php7.php:0
%w%f %w%d   2. d() %sbug00476-002-php7.php:35
%w%f %w%d   3. c() %sbug00476-002-php7.php:29
%w%f %w%d   4. b() %sbug00476-002-php7.php:20

Exception: Third exception in %sbug00476-002-php7.php on line 22

Call Stack:
%w%f %w%d   1. {main}() %sbug00476-002-php7.php:0
%w%f %w%d   2. d() %sbug00476-002-php7.php:35
%w%f %w%d   3. c() %sbug00476-002-php7.php:29

Exception: Fourth exception in %sbug00476-002-php7.php on line 31

Call Stack:
%w%f %w%d   1. {main}() %sbug00476-002-php7.php:0
%w%f %w%d   2. d() %sbug00476-002-php7.php:35
